
<mujoco model="centipede">
  <include file="misc/skybox.xml" />
  <include file="misc/materials.xml" />
  <compiler angle="degree" coordinate="local" inertiafromgeom="true"/>

  <option integrator="RK4" timestep="0.01"/>

  <default>
    <joint armature="1" damping="1" limited="true"/>
    <geom conaffinity="0" condim="3" density="25.0" friction="1.5 0.1 0.1" margin="0.01" rgba="0.8 0.6 0.4 1" material="self"/>
  </default>

  <worldbody>
    <light cutoff="100" diffuse="1 1 1" dir="-0 0 -1.3" directional="true" exponent="1" pos="0 0 1.3" specular=".1 .1 .1"/>
    <geom conaffinity="1" condim="3" material="grid" name="floor" pos="0 0 0" rgba="0.8 0.9 0.8 1" size="60 60 60" type="plane"/>
    <body name="torso_0" pos="0 0 0.75">
      <geom name="torsoGeom_0" pos="0 0 0" size="0.25" type="sphere" density="100"/>
      <joint armature="0" damping="0" limited="false" margin="0.01" name="root" pos="0 0 0" type="free"/>
      
      <body name="legbody_0" pos="0.0 -0.28 0">
        <joint axis="0 0 1" name="lefthip_0" pos="0.0 0.0 0.0" range="-40 40" type="hinge"/>
        <geom fromto="0.0 0.0 0.0 0.0 -0.28 0.0" name="legGeom_0" size="0.08"  type="capsule"/>
        <body pos="0 -0.28 0" name="frontFoot_0">
          <joint axis="1 0 0" name="ankle_0" pos="0.0 0.0 0.0" range="30 100" type="hinge"/>
          <geom fromto="0.0 0.0 0.0 0 -0.6 0.0" name="ankleGeom_0" size="0.08"  type="capsule"/>
        </body>
      </body>
      
      
      <body name="legbody_1" pos="0.0 0.28 0">
        <joint axis="0 0 1" name="righthip_1" pos="0.0 0.0 0.0" range="-40 40" type="hinge"/>
        <geom fromto="0.0 0.0 0.0 0.0 0.28 0.0" name="legGeom_1" size="0.08"  type="capsule"/>
        <body pos="0 0.28 0" name="frontFoot_1">
          <joint axis="-1 0 0" name="ankle_1" pos="0.0 0.0 0.0" range="30 100" type="hinge"/>
          <geom fromto="0.0 0.0 0.0 0 0.6 0.0" name="ankleGeom_1" size="0.08"  type="capsule"/>
        </body>
      </body>
      
      
      <body name="torso_1" pos="0.50 0 0">
        <geom name="torsoGeom_1" pos="0 0 0" size="0.25" type="sphere" density="100"/>
        <joint axis="0 0 1" name="body_1" pos="-0.25 0.0 0.0" range="-20 20" type="hinge"/>
        <joint axis="0 1 0" name="bodyupdown_1" pos="-0.25 0.0 0.0" range="-10 30" type="hinge"/>
      
        
        <body name="legbody_2" pos="0.0 -0.28 0">
          <joint axis="0 0 1" name="lefthip_2" pos="0.0 0.0 0.0" range="-40 40" type="hinge"/>
          <geom fromto="0.0 0.0 0.0 0.0 -0.28 0.0" name="legGeom_2" size="0.08"  type="capsule"/>
          <body pos="0 -0.28 0" name="frontFoot_2">
            <joint axis="1 0 0" name="ankle_2" pos="0.0 0.0 0.0" range="30 100" type="hinge"/>
            <geom fromto="0.0 0.0 0.0 0 -0.6 0.0" name="ankleGeom_2" size="0.08"  type="capsule"/>
          </body>
        </body>
        
        
        <body name="legbody_3" pos="0.0 0.28 0">
          <joint axis="0 0 1" name="righthip_3" pos="0.0 0.0 0.0" range="-40 40" type="hinge"/>
          <geom fromto="0.0 0.0 0.0 0.0 0.28 0.0" name="legGeom_3" size="0.08"  type="capsule"/>
          <body pos="0 0.28 0" name="frontFoot_3">
            <joint axis="-1 0 0" name="ankle_3" pos="0.0 0.0 0.0" range="30 100" type="hinge"/>
            <geom fromto="0.0 0.0 0.0 0 0.6 0.0" name="ankleGeom_3" size="0.08"  type="capsule"/>
          </body>
        </body>
        
        
        <body name="torso_2" pos="0.50 0 0">
          <geom name="torsoGeom_2" pos="0 0 0" size="0.25" type="sphere" density="100"/>
          <joint axis="0 0 1" name="body_2" pos="-0.25 0.0 0.0" range="-20 20" type="hinge"/>
          <joint axis="0 1 0" name="bodyupdown_2" pos="-0.25 0.0 0.0" range="-10 30" type="hinge"/>
        
          
          <body name="legbody_4" pos="0.0 -0.28 0">
            <joint axis="0 0 1" name="lefthip_4" pos="0.0 0.0 0.0" range="-40 40" type="hinge"/>
            <geom fromto="0.0 0.0 0.0 0.0 -0.28 0.0" name="legGeom_4" size="0.08"  type="capsule"/>
            <body pos="0 -0.28 0" name="frontFoot_4">
              <joint axis="1 0 0" name="ankle_4" pos="0.0 0.0 0.0" range="30 100" type="hinge"/>
              <geom fromto="0.0 0.0 0.0 0 -0.6 0.0" name="ankleGeom_4" size="0.08"  type="capsule"/>
            </body>
          </body>
          
          
          <body name="legbody_5" pos="0.0 0.28 0">
            <joint axis="0 0 1" name="righthip_5" pos="0.0 0.0 0.0" range="-40 40" type="hinge"/>
            <geom fromto="0.0 0.0 0.0 0.0 0.28 0.0" name="legGeom_5" size="0.08"  type="capsule"/>
            <body pos="0 0.28 0" name="frontFoot_5">
              <joint axis="-1 0 0" name="ankle_5" pos="0.0 0.0 0.0" range="30 100" type="hinge"/>
              <geom fromto="0.0 0.0 0.0 0 0.6 0.0" name="ankleGeom_5" size="0.08"  type="capsule"/>
            </body>
          </body>
          
          
          <body name="torso_3" pos="0.50 0 0">
            <geom name="torsoGeom_3" pos="0 0 0" size="0.25" type="sphere" density="100"/>
            <joint axis="0 0 1" name="body_3" pos="-0.25 0.0 0.0" range="-20 20" type="hinge"/>
            <joint axis="0 1 0" name="bodyupdown_3" pos="-0.25 0.0 0.0" range="-10 30" type="hinge"/>
          
            
            <body name="legbody_6" pos="0.0 -0.28 0">
              <joint axis="0 0 1" name="lefthip_6" pos="0.0 0.0 0.0" range="-40 40" type="hinge"/>
              <geom fromto="0.0 0.0 0.0 0.0 -0.28 0.0" name="legGeom_6" size="0.08"  type="capsule"/>
              <body pos="0 -0.28 0" name="frontFoot_6">
                <joint axis="1 0 0" name="ankle_6" pos="0.0 0.0 0.0" range="30 100" type="hinge"/>
                <geom fromto="0.0 0.0 0.0 0 -0.6 0.0" name="ankleGeom_6" size="0.08"  type="capsule"/>
              </body>
            </body>
            
            
            <body name="legbody_7" pos="0.0 0.28 0">
              <joint axis="0 0 1" name="righthip_7" pos="0.0 0.0 0.0" range="-40 40" type="hinge"/>
              <geom fromto="0.0 0.0 0.0 0.0 0.28 0.0" name="legGeom_7" size="0.08"  type="capsule"/>
              <body pos="0 0.28 0" name="frontFoot_7">
                <joint axis="-1 0 0" name="ankle_7" pos="0.0 0.0 0.0" range="30 100" type="hinge"/>
                <geom fromto="0.0 0.0 0.0 0 0.6 0.0" name="ankleGeom_7" size="0.08"  type="capsule"/>
              </body>
            </body>
            
            
            <body name="torso_4" pos="0.50 0 0">
              <geom name="torsoGeom_4" pos="0 0 0" size="0.25" type="sphere" density="100"/>
              <joint axis="0 0 1" name="body_4" pos="-0.25 0.0 0.0" range="-20 20" type="hinge"/>
              <joint axis="0 1 0" name="bodyupdown_4" pos="-0.25 0.0 0.0" range="-10 30" type="hinge"/>
            
              
              <body name="legbody_8" pos="0.0 -0.28 0">
                <joint axis="0 0 1" name="lefthip_8" pos="0.0 0.0 0.0" range="-40 40" type="hinge"/>
                <geom fromto="0.0 0.0 0.0 0.0 -0.28 0.0" name="legGeom_8" size="0.08"  type="capsule"/>
                <body pos="0 -0.28 0" name="frontFoot_8">
                  <joint axis="1 0 0" name="ankle_8" pos="0.0 0.0 0.0" range="30 100" type="hinge"/>
                  <geom fromto="0.0 0.0 0.0 0 -0.6 0.0" name="ankleGeom_8" size="0.08"  type="capsule"/>
                </body>
              </body>
              
              
              <body name="legbody_9" pos="0.0 0.28 0">
                <joint axis="0 0 1" name="righthip_9" pos="0.0 0.0 0.0" range="-40 40" type="hinge"/>
                <geom fromto="0.0 0.0 0.0 0.0 0.28 0.0" name="legGeom_9" size="0.08"  type="capsule"/>
                <body pos="0 0.28 0" name="frontFoot_9">
                  <joint axis="-1 0 0" name="ankle_9" pos="0.0 0.0 0.0" range="30 100" type="hinge"/>
                  <geom fromto="0.0 0.0 0.0 0 0.6 0.0" name="ankleGeom_9" size="0.08"  type="capsule"/>
                </body>
              </body>
              
              
              <body name="torso_5" pos="0.50 0 0">
                <camera name="track" mode="track"  pos="0 -6 3" xyaxes="1 0 0 0 0.4 1"/>
                <geom name="torsoGeom_5" pos="0 0 0" size="0.25" type="sphere" density="100"/>
                <joint axis="0 0 1" name="body_5" pos="-0.25 0.0 0.0" range="-20 20" type="hinge"/>
                <joint axis="0 1 0" name="bodyupdown_5" pos="-0.25 0.0 0.0" range="-10 30" type="hinge"/>
              
                
                <body name="legbody_10" pos="0.0 -0.28 0">
                  <joint axis="0 0 1" name="lefthip_10" pos="0.0 0.0 0.0" range="-40 40" type="hinge"/>
                  <geom fromto="0.0 0.0 0.0 0.0 -0.28 0.0" name="legGeom_10" size="0.08"  type="capsule"/>
                  <body pos="0 -0.28 0" name="frontFoot_10">
                    <joint axis="1 0 0" name="ankle_10" pos="0.0 0.0 0.0" range="30 100" type="hinge"/>
                    <geom fromto="0.0 0.0 0.0 0 -0.6 0.0" name="ankleGeom_10" size="0.08"  type="capsule"/>
                  </body>
                </body>
                
                
                <body name="legbody_11" pos="0.0 0.28 0">
                  <joint axis="0 0 1" name="righthip_11" pos="0.0 0.0 0.0" range="-40 40" type="hinge"/>
                  <geom fromto="0.0 0.0 0.0 0.0 0.28 0.0" name="legGeom_11" size="0.08"  type="capsule"/>
                  <body pos="0 0.28 0" name="frontFoot_11">
                    <joint axis="-1 0 0" name="ankle_11" pos="0.0 0.0 0.0" range="30 100" type="hinge"/>
                    <geom fromto="0.0 0.0 0.0 0 0.6 0.0" name="ankleGeom_11" size="0.08"  type="capsule"/>
                  </body>
                </body>
                
                
                <body name="torso_6" pos="0.50 0 0">
                  <geom name="torsoGeom_6" pos="0 0 0" size="0.25" type="sphere" density="100"/>
                  <joint axis="0 0 1" name="body_6" pos="-0.25 0.0 0.0" range="-20 20" type="hinge"/>
                  <joint axis="0 1 0" name="bodyupdown_6" pos="-0.25 0.0 0.0" range="-10 30" type="hinge"/>
                
                  
                  <body name="legbody_12" pos="0.0 -0.28 0">
                    <joint axis="0 0 1" name="lefthip_12" pos="0.0 0.0 0.0" range="-40 40" type="hinge"/>
                    <geom fromto="0.0 0.0 0.0 0.0 -0.28 0.0" name="legGeom_12" size="0.08"  type="capsule"/>
                    <body pos="0 -0.28 0" name="frontFoot_12">
                      <joint axis="1 0 0" name="ankle_12" pos="0.0 0.0 0.0" range="30 100" type="hinge"/>
                      <geom fromto="0.0 0.0 0.0 0 -0.6 0.0" name="ankleGeom_12" size="0.08"  type="capsule"/>
                    </body>
                  </body>
                  
                  
                  <body name="legbody_13" pos="0.0 0.28 0">
                    <joint axis="0 0 1" name="righthip_13" pos="0.0 0.0 0.0" range="-40 40" type="hinge"/>
                    <geom fromto="0.0 0.0 0.0 0.0 0.28 0.0" name="legGeom_13" size="0.08"  type="capsule"/>
                    <body pos="0 0.28 0" name="frontFoot_13">
                      <joint axis="-1 0 0" name="ankle_13" pos="0.0 0.0 0.0" range="30 100" type="hinge"/>
                      <geom fromto="0.0 0.0 0.0 0 0.6 0.0" name="ankleGeom_13" size="0.08"  type="capsule"/>
                    </body>
                  </body>
                  
                  
                  <body name="torso_7" pos="0.50 0 0">
                    <geom name="torsoGeom_7" pos="0 0 0" size="0.25" type="sphere" density="100"/>
                    <joint axis="0 0 1" name="body_7" pos="-0.25 0.0 0.0" range="-20 20" type="hinge"/>
                    <joint axis="0 1 0" name="bodyupdown_7" pos="-0.25 0.0 0.0" range="-10 30" type="hinge"/>
                  
                    
                    <body name="legbody_14" pos="0.0 -0.28 0">
                      <joint axis="0 0 1" name="lefthip_14" pos="0.0 0.0 0.0" range="-40 40" type="hinge"/>
                      <geom fromto="0.0 0.0 0.0 0.0 -0.28 0.0" name="legGeom_14" size="0.08"  type="capsule"/>
                      <body pos="0 -0.28 0" name="frontFoot_14">
                        <joint axis="1 0 0" name="ankle_14" pos="0.0 0.0 0.0" range="30 100" type="hinge"/>
                        <geom fromto="0.0 0.0 0.0 0 -0.6 0.0" name="ankleGeom_14" size="0.08"  type="capsule"/>
                      </body>
                    </body>
                    
                    
                    <body name="legbody_15" pos="0.0 0.28 0">
                      <joint axis="0 0 1" name="righthip_15" pos="0.0 0.0 0.0" range="-40 40" type="hinge"/>
                      <geom fromto="0.0 0.0 0.0 0.0 0.28 0.0" name="legGeom_15" size="0.08"  type="capsule"/>
                      <body pos="0 0.28 0" name="frontFoot_15">
                        <joint axis="-1 0 0" name="ankle_15" pos="0.0 0.0 0.0" range="30 100" type="hinge"/>
                        <geom fromto="0.0 0.0 0.0 0 0.6 0.0" name="ankleGeom_15" size="0.08"  type="capsule"/>
                      </body>
                    </body>
                    
                    
                    <body name="torso_8" pos="0.50 0 0">
                      <geom name="torsoGeom_8" pos="0 0 0" size="0.25" type="sphere" density="100"/>
                      <joint axis="0 0 1" name="body_8" pos="-0.25 0.0 0.0" range="-20 20" type="hinge"/>
                      <joint axis="0 1 0" name="bodyupdown_8" pos="-0.25 0.0 0.0" range="-10 30" type="hinge"/>
                    
                      
                      <body name="legbody_16" pos="0.0 -0.28 0">
                        <joint axis="0 0 1" name="lefthip_16" pos="0.0 0.0 0.0" range="-40 40" type="hinge"/>
                        <geom fromto="0.0 0.0 0.0 0.0 -0.28 0.0" name="legGeom_16" size="0.08"  type="capsule"/>
                        <body pos="0 -0.28 0" name="frontFoot_16">
                          <joint axis="1 0 0" name="ankle_16" pos="0.0 0.0 0.0" range="30 100" type="hinge"/>
                          <geom fromto="0.0 0.0 0.0 0 -0.6 0.0" name="ankleGeom_16" size="0.08"  type="capsule"/>
                        </body>
                      </body>
                      
                      
                      <body name="legbody_17" pos="0.0 0.28 0">
                        <joint axis="0 0 1" name="righthip_17" pos="0.0 0.0 0.0" range="-40 40" type="hinge"/>
                        <geom fromto="0.0 0.0 0.0 0.0 0.28 0.0" name="legGeom_17" size="0.08"  type="capsule"/>
                        <body pos="0 0.28 0" name="frontFoot_17">
                          <joint axis="-1 0 0" name="ankle_17" pos="0.0 0.0 0.0" range="30 100" type="hinge"/>
                          <geom fromto="0.0 0.0 0.0 0 0.6 0.0" name="ankleGeom_17" size="0.08"  type="capsule"/>
                        </body>
                      </body>
                    </body>
                  </body>
                </body>
              </body>
            </body>
          </body>
        </body>
      </body>

    </body>
  </worldbody>
  <actuator>
    <motor ctrllimited="true" ctrlrange="-1.0 1.0" joint="lefthip_0"    name="lefthip_0"       gear="150"/>
    <motor ctrllimited="true" ctrlrange="-1.0 1.0" joint="ankle_0"      name="ankle_0"       gear="150"/>
    <motor ctrllimited="true" ctrlrange="-1.0 1.0" joint="righthip_1"   name="righthip_1"       gear="150"/>
    <motor ctrllimited="true" ctrlrange="-1.0 1.0" joint="ankle_1"      name="ankle_1"       gear="150"/>
    <motor ctrllimited="true" ctrlrange="-1.0 1.0" joint="lefthip_2"    name="lefthip_2"       gear="150"/>
    <motor ctrllimited="true" ctrlrange="-1.0 1.0" joint="ankle_2"      name="ankle_2"       gear="150"/>
    <motor ctrllimited="true" ctrlrange="-1.0 1.0" joint="righthip_3"   name="righthip_3"       gear="150"/>
    <motor ctrllimited="true" ctrlrange="-1.0 1.0" joint="ankle_3"      name="ankle_3"       gear="150"/>
    <motor ctrllimited="true" ctrlrange="-1.0 1.0" joint="body_1"       name="body_1"       gear="100"/>
    <motor ctrllimited="true" ctrlrange="-1.0 1.0" joint="bodyupdown_1" name="bodyupdown_1"       gear="100"/>
    <motor ctrllimited="true" ctrlrange="-1.0 1.0" joint="lefthip_4"    name="lefthip_4"       gear="150"/>
    <motor ctrllimited="true" ctrlrange="-1.0 1.0" joint="ankle_4"      name="ankle_4"       gear="150"/>
    <motor ctrllimited="true" ctrlrange="-1.0 1.0" joint="righthip_5"   name="righthip_5"       gear="150"/>
    <motor ctrllimited="true" ctrlrange="-1.0 1.0" joint="ankle_5"      name="ankle_5"       gear="150"/>
    <motor ctrllimited="true" ctrlrange="-1.0 1.0" joint="body_2"       name="body_2"       gear="100"/>
    <motor ctrllimited="true" ctrlrange="-1.0 1.0" joint="bodyupdown_2" name="bodyupdown_2"       gear="100"/>
    <motor ctrllimited="true" ctrlrange="-1.0 1.0" joint="lefthip_6"    name="lefthip_6"       gear="150"/>
    <motor ctrllimited="true" ctrlrange="-1.0 1.0" joint="ankle_6"      name="ankle_6"       gear="150"/>
    <motor ctrllimited="true" ctrlrange="-1.0 1.0" joint="righthip_7"   name="righthip_7"       gear="150"/>
    <motor ctrllimited="true" ctrlrange="-1.0 1.0" joint="ankle_7"      name="ankle_7"       gear="150"/>
    <motor ctrllimited="true" ctrlrange="-1.0 1.0" joint="body_3"       name="body_3"       gear="100"/>
    <motor ctrllimited="true" ctrlrange="-1.0 1.0" joint="bodyupdown_3" name="bodyupdown_3"       gear="100"/>
    <motor ctrllimited="true" ctrlrange="-1.0 1.0" joint="lefthip_8"    name="lefthip_8"       gear="150"/>
    <motor ctrllimited="true" ctrlrange="-1.0 1.0" joint="ankle_8"      name="ankle_8"       gear="150"/>
    <motor ctrllimited="true" ctrlrange="-1.0 1.0" joint="righthip_9"   name="righthip_9"       gear="150"/>
    <motor ctrllimited="true" ctrlrange="-1.0 1.0" joint="ankle_9"      name="ankle_9"       gear="150"/>
    <motor ctrllimited="true" ctrlrange="-1.0 1.0" joint="body_4"       name="body_4"       gear="100"/>
    <motor ctrllimited="true" ctrlrange="-1.0 1.0" joint="bodyupdown_4" name="bodyupdown_4"       gear="100"/>
    <motor ctrllimited="true" ctrlrange="-1.0 1.0" joint="lefthip_10"   name="lefthip_10"       gear="150"/>
    <motor ctrllimited="true" ctrlrange="-1.0 1.0" joint="ankle_10"     name="ankle_10"       gear="150"/>
    <motor ctrllimited="true" ctrlrange="-1.0 1.0" joint="righthip_11"  name="righthip_11"       gear="150"/>
    <motor ctrllimited="true" ctrlrange="-1.0 1.0" joint="ankle_11"     name="ankle_11"       gear="150"/>
    <motor ctrllimited="true" ctrlrange="-1.0 1.0" joint="body_5"       name="body_5"       gear="100"/>
    <motor ctrllimited="true" ctrlrange="-1.0 1.0" joint="bodyupdown_5" name="bodyupdown_5"       gear="100"/>
    <motor ctrllimited="true" ctrlrange="-1.0 1.0" joint="lefthip_12"   name="lefthip_12"       gear="150"/>
    <motor ctrllimited="true" ctrlrange="-1.0 1.0" joint="ankle_12"     name="ankle_12"       gear="150"/>
    <motor ctrllimited="true" ctrlrange="-1.0 1.0" joint="righthip_13"  name="righthip_13"       gear="150"/>
    <motor ctrllimited="true" ctrlrange="-1.0 1.0" joint="ankle_13"     name="ankle_13"       gear="150"/>
    <motor ctrllimited="true" ctrlrange="-1.0 1.0" joint="body_6"       name="body_6"       gear="100"/>
    <motor ctrllimited="true" ctrlrange="-1.0 1.0" joint="bodyupdown_6" name="bodyupdown_6"       gear="100"/>
    <motor ctrllimited="true" ctrlrange="-1.0 1.0" joint="lefthip_14"   name="lefthip_14"       gear="150"/>
    <motor ctrllimited="true" ctrlrange="-1.0 1.0" joint="ankle_14"     name="ankle_14"       gear="150"/>
    <motor ctrllimited="true" ctrlrange="-1.0 1.0" joint="righthip_15"  name="righthip_15"       gear="150"/>
    <motor ctrllimited="true" ctrlrange="-1.0 1.0" joint="ankle_15"     name="ankle_15"       gear="150"/>
    <motor ctrllimited="true" ctrlrange="-1.0 1.0" joint="body_7"       name="body_7"       gear="100"/>
    <motor ctrllimited="true" ctrlrange="-1.0 1.0" joint="bodyupdown_7" name="bodyupdown_7"       gear="100"/>
    <motor ctrllimited="true" ctrlrange="-1.0 1.0" joint="lefthip_16"   name="lefthip_16"       gear="150"/>
    <motor ctrllimited="true" ctrlrange="-1.0 1.0" joint="ankle_16"     name="ankle_16"       gear="150"/>
    <motor ctrllimited="true" ctrlrange="-1.0 1.0" joint="righthip_17"  name="righthip_17"       gear="150"/>
    <motor ctrllimited="true" ctrlrange="-1.0 1.0" joint="ankle_17"     name="ankle_17"       gear="150"/>
    <motor ctrllimited="true" ctrlrange="-1.0 1.0" joint="body_8"       name="body_8"       gear="100"/>
    <motor ctrllimited="true" ctrlrange="-1.0 1.0" joint="bodyupdown_8" name="bodyupdown_8"       gear="100"/>
  </actuator>
  <custom>
    <numeric data="0.0 0.0 0.55 1.0 0.0 0.0 0.0 0.0 -1.0 0.0 1.0 0.0 -1.0 0.0 1.0 0.0 -1.0 0.0 1.0 0.0 -1.0 0.0 1.0 0.0 -1.0 0.0 1.0 0.0 -1.0 0.0 1.0 0.0 -1.0 0.0 1.0 0.0 -1.0 0.0 1.0 0.0 -1.0 0.0 1.0" name="init_qpos"/>
  </custom>

</mujoco>
